Workbook

Sheet Summary
A1: Strata - mod tracker summary ("Build. Fly. Explore.")
A2: Counts update from the Mods sheet. Edit Status and 1.21.1 NeoForge there (dropdowns).
A4: Pillar | B4: Keep | C4: Maybe | D4: Cut | E4: Total
A5: Core | B5: =COUNTIFS(Mods!$C:$C,$A5,Mods!$F:$F,"Keep") | C5: =COUNTIFS(Mods!$C:$C,$A5,Mods!$F:$F,"Maybe") | D5: =COUNTIFS(Mods!$C:$C,$A5,Mods!$F:$F,"Cut") | E5: =SUM(B5:D5)
A6: Tech | B6: =COUNTIFS(Mods!$C:$C,$A6,Mods!$F:$F,"Keep") | C6: =COUNTIFS(Mods!$C:$C,$A6,Mods!$F:$F,"Maybe") | D6: =COUNTIFS(Mods!$C:$C,$A6,Mods!$F:$F,"Cut") | E6: =SUM(B6:D6)
A7: Magic | B7: =COUNTIFS(Mods!$C:$C,$A7,Mods!$F:$F,"Keep") | C7: =COUNTIFS(Mods!$C:$C,$A7,Mods!$F:$F,"Maybe") | D7: =COUNTIFS(Mods!$C:$C,$A7,Mods!$F:$F,"Cut") | E7: =SUM(B7:D7)
A8: Exploration | B8: =COUNTIFS(Mods!$C:$C,$A8,Mods!$F:$F,"Keep") | C8: =COUNTIFS(Mods!$C:$C,$A8,Mods!$F:$F,"Maybe") | D8: =COUNTIFS(Mods!$C:$C,$A8,Mods!$F:$F,"Cut") | E8: =SUM(B8:D8)
A9: Pokemon world | B9: =COUNTIFS(Mods!$C:$C,$A9,Mods!$F:$F,"Keep") | C9: =COUNTIFS(Mods!$C:$C,$A9,Mods!$F:$F,"Maybe") | D9: =COUNTIFS(Mods!$C:$C,$A9,Mods!$F:$F,"Cut") | E9: =SUM(B9:D9)
A10: Life | B10: =COUNTIFS(Mods!$C:$C,$A10,Mods!$F:$F,"Keep") | C10: =COUNTIFS(Mods!$C:$C,$A10,Mods!$F:$F,"Maybe") | D10: =COUNTIFS(Mods!$C:$C,$A10,Mods!$F:$F,"Cut") | E10: =SUM(B10:D10)
A11: Visuals | B11: =COUNTIFS(Mods!$C:$C,$A11,Mods!$F:$F,"Keep") | C11: =COUNTIFS(Mods!$C:$C,$A11,Mods!$F:$F,"Maybe") | D11: =COUNTIFS(Mods!$C:$C,$A11,Mods!$F:$F,"Cut") | E11: =SUM(B11:D11)
A12: Performance | B12: =COUNTIFS(Mods!$C:$C,$A12,Mods!$F:$F,"Keep") | C12: =COUNTIFS(Mods!$C:$C,$A12,Mods!$F:$F,"Maybe") | D12: =COUNTIFS(Mods!$C:$C,$A12,Mods!$F:$F,"Cut") | E12: =SUM(B12:D12)
A13: Total | B13: =SUM(B5:B12) | C13: =SUM(C5:C12) | D13: =SUM(D5:D12) | E13: =SUM(E5:E12)
A15: 1.21.1 NeoForge (Keep + Maybe) | B15: Count
A16: Confirmed | B16: =COUNTIFS(Mods!$G:$G,$A16,Mods!$F:$F,"<>Cut")
A17: Verify | B17: =COUNTIFS(Mods!$G:$G,$A17,Mods!$F:$F,"<>Cut")
A18: Not available | B18: =COUNTIFS(Mods!$G:$G,$A18,Mods!$F:$F,"<>Cut")
A20: Legend
A21: Status: Keep = in the pack; Maybe = undecided; Cut = decided against (kept for the record).
A22: 1.21.1 NeoForge: Confirmed = a 1.21.1 NeoForge build was seen during planning (file page or a 1.21.1 NeoForge modlist); Verify = check in Claude Code via CurseForge/Modrinth; Not available = no build exists.
A23: Flags: Config / KubeJS = needs a tweak; Gate = progression-gated; Test = must be play-tested; Check flight = review against the flight rule.
A24: Side: Client = only players install it; Server = only the server; Both = everyone.
A25: 'Pick one' rows are open questions; replace with the chosen mod.
A26: Dependency libraries (Balm, Moonlight Lib, GeckoLib, etc.) are pulled in automatically by packwiz and are not all listed.

Sheet Mods
A1: Mod | B1: Category | C1: Pillar | D1: Needs / compat with | E1: Side | F1: Status | G1: 1.21.1 NeoForge | H1: Flags | I1: Notes | J1: Phase 1 lookup
A2: NeoForge (loader) | B2: Core | C2: Core | E2: Both | F2: Keep | G2: Confirmed | I2: Minecraft 1.21.1
A3: KubeJS | B3: Core | C3: Core | D3: Rhino | E3: Both | F3: Keep | G3: Confirmed | I3: Recipe changes, gating, hiding items | J3: MR kubejs 2101.7.2
A4: FTB Quests | B4: Core | C4: Core | D4: FTB Library | E4: Both | F4: Keep | G4: Confirmed | I4: Quest chapters per mod and boss + cozy chapter | J4: CF ftb-quests-forge 2101.1.37 (Modrinth hit was only a zh_cn translation)
A5: Almost Unified | B5: Core | C5: Tech | E5: Both | F5: Keep | G5: Confirmed | I5: Required: collapses duplicate ores/ingots | J5: MR almostunified 1.4.2
A6: Curios API | B6: Core | C6: Core | E6: Both | F6: Keep | G6: Confirmed | I6: Standard accessory slot system | J6: MR curios 9.5.1
A7: Accessories + Accessories Compatibility Layer | B7: Core | C7: Core | E7: Both | F7: Maybe | G7: Confirmed | I7: Only if a mod needs Accessories instead of Curios | J7: MR accessories 1.1.0-beta.54 + accessories-compat-layer 0.1.13 (not added: Maybe)
A8: Polymorph | B8: QoL | C8: Core | E8: Both | F8: Keep | G8: Confirmed | I8: Pick result when recipes conflict | J8: MR polymorph 1.2.0 (beta). Not Polymorph+ (different mod)
A9: Create | B9: Create | C9: Tech | E9: Both | F9: Keep | G9: Confirmed | I9: Must-have | J9: MR create 6.0.10
A10: Create Aeronautics | B10: Create: flight | C10: Tech | D10: Create, Sable | E10: Both | F10: Keep | G10: Confirmed | I10: Must-have; forces 1.21.1 NeoForge | J10: MR create-aeronautics 1.3.2. Known: visual issues with Iris shaders
A11: Sable | B11: Create: flight | C11: Tech | E11: Both | F11: Keep | G11: Confirmed | I11: Required by Aeronautics | J11: MR sable 2.0.6
A12: Create Aeronautics: Gadgets & Gizmos | B12: Create: flight | C12: Tech | D12: Aeronautics | E12: Both | F12: Keep | G12: Confirmed | J12: Was 'Create Thrusters'. MR create-aeronautics-gadgets-and-gizmos 1.2.10, PINNED (2.0 is in rapid pre-release)
A13: Create Propulsion: Simulated | B13: Create: flight | C13: Tech | D13: Aeronautics | E13: Both | F13: Keep | G13: Confirmed | J13: MR create-propulsion-simulated 1.1.5
A14: Create Aeroworks | B14: Create: flight | C14: Tech | D14: Aeronautics | E14: Both | F14: Keep | G14: Confirmed | J14: MR create-aeroworks 1.5.0
A15: Drive-By-Wire with Sable | B15: Create: flight | C15: Tech | D15: Aeronautics | E15: Both | F15: Keep | G15: Confirmed | J15: Was 'Drive By Wire' (original Forge-only). MR drive-by-wire-sable 0.3.0
A16: Create Tweaked Controllers | B16: Create: flight | C16: Tech | D16: Create | E16: Both | F16: Keep | G16: Confirmed | H16: Test | I16: Check it doesn't fight Aeronautics controls | J16: MR create-tweaked-controllers 1.2.7
A17: Create Offroad | B17: Create: vehicles | C17: Tech | D17: Create | E17: Both | F17: Keep | G17: Confirmed | H17: Test | I17: Adds physics load; include in perf test | J17: Bundled inside Create Aeronautics (Simulated/Aeronautics/Offroad modules). Nothing separate to add
A18: Create Big Cannons | B18: Create: combat | C18: Tech | D18: Create | E18: Both | F18: Keep | G18: Confirmed | H18: Config | I18: Limit block damage; claims block explosions | J18: MR create-big-cannons 5.11.7
A19: Create Crafts & Additions | B19: Create: power | C19: Tech | D19: Create | E19: Both | F19: Keep | G19: Confirmed | H19: Config | I19: Early power; lower alternator FE output; its wires for local runs | J19: MR createaddition 1.7.2 (beta)
A20: Create: New Age | B20: Create: power | C20: Tech | D20: Create | E20: Both | F20: Keep | G20: Confirmed | H20: KubeJS | I20: Mid-game generators + nuclear; remove its wire recipes | J20: MR create-new-age 1.2.0
A21: Create: Better Motors | B21: Create: power | C21: Tech | D21: Crafts & Additions | E21: Both | F21: Maybe | G21: Confirmed | I21: Skipped for now; add if alternators feel weak | J21: MR create-better-motors 4.0.0 (not added: Maybe)
A22: Create Diesel Generators | B22: Create: power | C22: Tech | D22: Create | E22: Both | F22: Keep | G22: Confirmed | I22: Fuel engine, not a converter | J22: MR create-diesel-generators 1.3.15
A23: Create Enchantment Industry | B23: Create: processing | C23: Tech | D23: Create | E23: Both | F23: Keep | G23: Confirmed | J23: MR create-enchantment-industry 2.5.4b
A24: Create Slice & Dice | B24: Create: processing | C24: Tech | D24: Create, Farmer's Delight | E24: Both | F24: Keep | G24: Confirmed | I24: Automated cooking | J24: MR slice-and-dice 4.3.4
A25: Create Central Kitchen | B25: Create: processing | C25: Tech | D25: Create, Farmer's Delight | E25: Both | F25: Keep | G25: Confirmed | J25: MR create-central-kitchen 2.6.2b
A26: Create: Steam 'n' Rails | B26: Create: trains | C26: Tech | D26: Create | E26: Both | F26: Keep | G26: Confirmed | J26: Official: 1.20.1 only. Using unofficial port 'Steam 'n' Rails Neoforge' (MR create-steam-n-rails-1.21.1 0.3.0-beta.2). Known: snow-track crash (port issue #361)
A27: Create Additional Logistics | B27: Create: logistics | C27: Tech | D27: Create | E27: Both | F27: Keep | G27: Confirmed | J27: MR create-additional-logistics 1.4.5
A28: Create Numismatics | B28: Create: logistics | C28: Tech | D28: Create | E28: Both | F28: Keep | G28: Confirmed | I28: Currency | J28: MR numismatics 1.1.0
A29: Create Trading Floor | B29: Create: logistics | C29: Tech | D29: Create | E29: Both | F29: Keep | G29: Confirmed | J29: MR create-trading-floor 3.0.16
A30: Create Copycats+ | B30: Create: building | C30: Tech | D30: Create | E30: Both | F30: Keep | G30: Confirmed | J30: MR copycats 3.0.9
A31: Create Deco | B31: Create: building | C31: Tech | D31: Create | E31: Both | F31: Keep | G31: Confirmed | J31: MR create-deco 2.1.3
A32: Create Connected | B32: Create: building | C32: Tech | D32: Create | E32: Both | F32: Keep | G32: Confirmed | J32: MR create-connected 1.3.3
A33: Create: Bits 'n' Bobs | B33: Create: parts | C33: Tech | D33: Create | E33: Both | F33: Keep | G33: Confirmed | J33: MR create-bits-n-bobs 2.3.5
A34: Create: Transmission | B34: Create: parts | C34: Tech | D34: Create | E34: Both | F34: Keep | G34: Confirmed | J34: MR create-transmission 1.2.2
A35: Create: FE Converter | B35: Create: power | C35: Tech | E35: Both | F35: Cut | G35: Not available | I35: Discontinued (source lost)
A36: Mekanism | B36: Tech | C36: Tech | E36: Both | F36: Keep | G36: Confirmed | I36: Must-have | J36: MR mekanism 10.7.19
A37: Mekanism Generators | B37: Tech | C37: Tech | D37: Mekanism | E37: Both | F37: Keep | G37: Confirmed | J37: MR mekanism-generators 10.7.19
A38: Mekanism Tools | B38: Tech | C38: Tech | D38: Mekanism | E38: Both | F38: Keep | G38: Confirmed | J38: MR mekanism-tools 10.7.19
A39: Applied Mekanistics | B39: Tech | C39: Tech | D39: Mekanism, AE2 | E39: Both | F39: Keep | G39: Confirmed | J39: MR applied-mekanistics 1.6.3
A40: Applied Energistics 2 | B40: Storage | C40: Tech | E40: Both | F40: Keep | G40: Confirmed | H40: Gate | I40: Must-have; Quantum Network Bridge late-game | J40: MR ae2 19.2.18
...
